# Исключения
## Как примерно работает throw
Исключение фактически "возвращается" методом, несмотря на то, что для возвращаемого объекта обычно предусмотрен совсем другой тип.<br/>
Таким образом, можно говорить, что обработка исключений - альтернативный механизм возврата из исполняемого метода.<br/>
_Эккель Б. Философия Java. 4-е полное изд. Стр. 368_

## Простейший пример Error Handler'а
Тут идет просто логирование.
```java
static void logException(Exception e) {
    StringWriter trace = new StringWriter();
    e.printStackTrace(new PrintWriter(trace));
    logger.severe(trace.toString());
}

public static void main(String[] args) {
    try {
        throw new NullPointerException();
    } catch (NullPointerException e) {
        logException(e);
    }
}
```
_Эккель Б. Философия Java. 4-е полное изд. Стр. 374_

## Правильная цепочка перехватов исключений
Перехватывать Exception или Throwable нужно в конце цепочки иначе последующие блоки `catch` будут проигнорированы.<br/>
_Эккель Б. Философия Java. 4-е полное изд. Стр. 377_<br/>
В противном случае, будет получена ошибка компилятора<br/>
_Эккель Б. Философия Java. 4-е полное изд. Стр. 403_

## Перегрузка `printStackTrace`
* `printStackTrace()`
* `printStackTrace(PrintStream)`
* `printStackTrace(java.io.PrintWriter)`

[Пакет с примерами](examples/java/exceptions/stack_trace/print_stack_trace)<br/>
_Эккель Б. Философия Java. 4-е полное изд. Стр. 377_

## `Object.getClass(`), `getName()`, `getSimpleName()`
Метод `getClass()` возвращает информацию об объекте.<br/>
Отсюда можно узнать имя объекта, включая пакет (`getName()`) или же имя класса без уточнений (`getSimpleName()`)<br/>
_Эккель Б. Философия Java. 4-е полное изд. Стр. 378_

## Получить массив трассировки исключения `getStacktrace`
При помощи `getStacktrace` можно получить массив трассировки. Он же выводится при `printStacktrace`<br/>
[Пример](examples/java/exceptions/stack_trace/GetStackTrace.java)<br/>
_Эккель Б. Философия Java. 4-е полное изд. Стр. 379_

## Дополнение трассировки текущим методом для переброски его дальше
При помощи `fillStackTrace` можно перебросить полученное исключение дальше, дополнив его текущим местом.<br/>
Если этого не сделать, то в нем будет информация только относительно того места, где оно было возбуждено.<br/>
[Пример](examples/java/exceptions/stack_trace/WithFillingStackTrace.java)
```java
} catch (Exception e) {
    throw (Exception) e.fillStackTrace();
}
```
[Пример с потерей](examples/java/exceptions/stack_trace/WithoutFillingStackTrace.java)<br/>
_Эккель Б. Философия Java. 4-е полное изд. Стр. 380_

## Возбуждение исключения не теряя информации о перехваченном другом исключении
Если нужно образовать цепочку исключений, можно воспользоваться методом `initCause`<br/>
[Пример](examples/java/exceptions/init_cause/ThrowWithInitCause.java)
```java
} catch (SomeException e1) {
    AnotherException e2 = new AnotherException();
    e2.initCause(e1);
    throw e2;
}
```
[Пример с задачей в конструкторе](examples/java/exceptions/init_cause/ThrowWithCauseInConstructor.java)<br/>
[Пример с потерей](examples/java/exceptions/init_cause/ThrowWithoutInitCauseAndConstructor.java)<br/>
_Эккель Б. Философия Java. 4-е полное изд. Стр. 382_

## Получение исключения, являющегося причиной исключения
`getCause()`<br/>
_Эккель Б. Философия Java. 4-е полное изд. Стр. 410_

## `finally` и неотловленное исключение
Даже если исключение не перехвачено в текущем блоке `try-catch`, блок `finally` отработает перед тем, как механизм обработки исключений продолжит поиск обработчика на более высоком уровне<br/>
[Пример](examples/java/exceptions/finally_execution/FinallyAndAncaughtException.java)<br/>
_Эккель Б. Философия Java. 4-е полное изд. Стр. 390_

## `finally` и `break`/`continue`
Блок finally также исполняется в ситуациях, где используются операторы `break` и `continue`<br/>
[Пример](examples/java/exceptions/finally_execution/FinallyAndBreak.java)<br/>
[Пример](examples/java/exceptions/finally_execution/FinallyAndContinue.java)<br/>
_Эккель Б. Философия Java. 4-е полное изд. Стр. 391_

## `finally` и `return`
Неважно из какой точки был совершен `return`, `finally` выполниться перед возвратом метода<br/>
[Пример](examples/java/exceptions/finally_execution/FinallyAndReturn.java)
```java
try {
    System.out.println("Точка 1");
    if (i == 1) return;
    System.out.println("Точка 2");
    if (i == 1) return;
    System.out.println("Точка 3");
    if (i == 1) return;
} finally {
    System.out.println("Блок finally");
}
```
При вызове блока с передачей `i` от 1 до 3 будет такой вывод (В конце, в `main` выводится Конец)
```
Точка 1
Блок finally
Конец
Точка 1
Точка 2
Блок finally
Конец
Точка 1
Точка 2
Точка 3
Блок finally
Конец
```
_Эккель Б. Философия Java. 4-е полное изд. Стр. 391_

## Потеря исключения с `finally` №1
[Пример](examples/java/exceptions/finally_lost_exception/LostByAnotherException.java)
```java
try {
    throw new VeryImportantException();
} finally {
    throw new NotVeryImportantException();
}
```
_Эккель Б. Философия Java. 4-е полное изд. Стр. 393_

## Потеря исключения с `finally` №2
[Пример](examples/java/exceptions/finally_lost_exception/LostByReturn.java)
```java
try {
    throw new VeryImportantException();
} finally {
    return;
}
```
_Эккель Б. Философия Java. 4-е полное изд. Стр. 393_